Workbook
Name ETRI_off: #REF!
Name ETRI_on: #REF!
Name markups: #REF!

Sheet READ_ME
A2: Notes on commodity prices in IESA-Opt
A4: Units: | B4: Prices are given in constant EUR2022 except where otherwise specified
A5: Scope: | B5: Exogenous prices are applied to commodities that come from outside the boundary of the optimization. This applies mainly to fuels/energy carriers imported from outside the geographical boundary (NL), but can also apply to commodities purchased from outside the energy system, such as agricultural byproducts, municipal waste, or primary energy carriers with extraction costs not modelled explicitly (like domestic oil or natural gas). In some cases, multiple "commodities" can be defined in IESA-Opt for a single energy carrier. This can be used to approximate a cost curve, or differing transport costs for purchases of the same commodity from different regions.

Sheet Commodity_prices_MEUR2022
A1: Name | B1: Unit | C1: 2022 | D1: 2025 | E1: 2030 | F1: 2035 | G1: 2040 | H1: 2045 | I1: 2050 | J1: Updated | K1: Source | L1: Notes
A2: Imported LPG - Refineries | B2: M€2022/PJ | C2: =AVERAGE('Prices wo taxes'!$FO$98:$FO$148)*1.915/45.2 -> 25.331964 | D2: =(D20*($C$2/$C$20)) -> 23.51929 | E2: =(E20*($C$2/$C$20)) -> 21.713112 | F2: =(F20*($C$2/$C$20)) -> 21.713112 | G2: =(G20*($C$2/$C$20)) -> 16.284834 | H2: =(H20*($C$2/$C$20)) -> 15.645066 | I2: =(I20*($C$2/$C$20)) -> 14.992387 | J2: 45582 | K2: EC Weekly Oil Bulletin | L2: Average of weekly 2022 fuel oil prices for NL reported in oil bulletin. Assumed 45.2 MJ/kg per RVO NCV for LPG, and 1915 l/t as per IEA statistics manual. Future years assume constant ratio for refined products to crude oil.
A3: Imported Naphtha - Refineries | B3: M€2022/PJ | C3: =other_sources!B93 -> 16.619183 | D3: =(D20*($C$3/$C$20)) -> 15.429968 | E3: =(E20*($C$3/$C$20)) -> 14.245014 | F3: =(F20*($C$3/$C$20)) -> 14.245014 | G3: =(G20*($C$3/$C$20)) -> 10.683761 | H3: =(H20*($C$3/$C$20)) -> 10.264037 | I3: =(I20*($C$3/$C$20)) -> 9.8358432 | J3: 45582 | K3: BASF key prices | L3: Base year prices reported by BASF (annual average price for 2022). Projections are based on ratio of naphtha to crude oil price.
A4: Imported Road Fuel - Refineries | B4: M€2022/PJ | C4: =AVERAGE('Prices wo taxes'!$FJ$98:$FJ$148)*1.35/43.3 -> 31.52515 | D4: =(D20*($C$4/$C$20)) -> 29.269311 | E4: =(E20*($C$4/$C$20)) -> 27.021557 | F4: =(F20*($C$4/$C$20)) -> 27.021557 | G4: =(G20*($C$4/$C$20)) -> 20.266168 | H4: =(H20*($C$4/$C$20)) -> 19.469989 | I4: =(I20*($C$4/$C$20)) -> 18.657742 | J4: 45582 | K4: EC Weekly Oil Bulletin | L4: Average of weekly 2022 fuel oil prices for NL reported in oil bulletin. Assumed 43.3 MJ/kg per RVO NCV for gasoline, and 1350 l/t as per IEA statistics manual. Future years assume constant ratio for refined products to crude oil.
A5: Imported Kerosene - Refineries | B5: M€2022/PJ | C5: =AVERAGE('Prices wo taxes'!$FL$98:$FL$148)*1.246/43.92 -> 30.374081 | D5: =(D20*($C$5/$C$20)) -> 28.200609 | E5: =(E20*($C$5/$C$20)) -> 26.034927 | F5: =(F20*($C$5/$C$20)) -> 26.034927 | G5: =(G20*($C$5/$C$20)) -> 19.526195 | H5: =(H20*($C$5/$C$20)) -> 18.759086 | I5: =(I20*($C$5/$C$20)) -> 17.976497 | J5: 45582 | K5: EC Weekly Oil Bulletin; IEA 2024 | L5: Used gas/diesel oil as a proxy. Average of weekly 2022 fuel oil prices for NL reported in oil bulletin. Assumed 43.2 MJ/kg per RVO NCV for gasoline, and 1185 l/t as per IEA statistics manual. Future years assume constant ratio for refined products to crude oil. Well aligned with prices for BE in IEA 2024 (End Use price explorer) - there NL data is only available for 2010.
A6: Imported Fuel Oil - Refineries | B6: M€2022/PJ | C6: =AVERAGE('Prices wo taxes'!$FM$98:$FM$148)/41 -> 17.62704 | D6: =(D20*($C$6/$C$20)) -> 16.365705 | E6: =(E20*($C$6/$C$20)) -> 15.108891 | F6: =(F20*($C$6/$C$20)) -> 15.108891 | G6: =(G20*($C$6/$C$20)) -> 11.331668 | H6: =(H20*($C$6/$C$20)) -> 10.886491 | I6: =(I20*($C$6/$C$20)) -> 10.43233 | J6: 45582 | K6: EC Weekly Oil Bulletin | L6: Average of weekly 2022 fuel oil prices for NL reported in oil bulletin. Assumed 41 MJ/kg per RVO NCV for residual fuel oil. Future years assume constant ratio for refined products to crude oil.
A7: Imported Other Oil Products - Refineries | B7: M€2022/PJ | C7: =C6 -> 17.62704 | D7: =D6 -> 16.365705 | E7: =E6 -> 15.108891 | F7: =F6 -> 15.108891 | G7: =G6 -> 11.331668 | H7: =H6 -> 10.886491 | I7: =I6 -> 10.43233 | J7: 45579 | K7: - | L7: Assumed equal to fuel oil.
A8: Imported Bionaphtha - Refineries | B8: M€2022/PJ | C8: =C3*2 -> 33.238367 | D8: =(($I8-$C8)/($I$1-$C$1))*(D$1-C$1)+C8 -> 31.813865 | E8: =(($I8-$C8)/($I$1-$C$1))*(E$1-D$1)+D8 -> 29.439696 | F8: =(($I8-$C8)/($I$1-$C$1))*(F$1-E$1)+E8 -> 27.065527 | G8: =(($I8-$C8)/($I$1-$C$1))*(G$1-F$1)+F8 -> 24.691358 | H8: =(($I8-$C8)/($I$1-$C$1))*(H$1-G$1)+G8 -> 22.317189 | I8: =C8*0.6 -> 19.94302 | J8: 45629 | K8: TNO 2020; IEA Bioenergy 2020 | L8: Assumed 2x price of fossil equivalent in base year, then 40% decline by 2050.
A9: Imported Bioethanol - Refineries | B9: M€2022/PJ | C9: =1.3/0.789*26.7/Conversions!AC4 -> 41.778153 | D9: =ROUND((C9+E9)/2,2) -> 38.04 | E9: =other_sources!C182 -> 34.3 | F9: =E9 -> 34.3 | G9: =F9 -> 34.3 | H9: =G9 -> 34.3 | I9: =H9 -> 34.3 | J9: 45625 | K9: TNO 2024; IEA 2021 | L9: 2022 price from IEA Renewables Market Report. European ethanol price of $1.3/liter. Ethanol market currently at a high point (see market report) due to supply shocks i.e. high price of key feedstocks like corn. We take TNO 2030 value as the longer term stable value, as price shock effects dissipate. Demand pressures are mixed (US & Europe loosening or keeping stable their blending requirements, while new requirements are implemented elsewhere i.e. India). Assumed equal to 2030/2050 price for bioethanol. Note TNO assumes significant price increase to 2050 (~4x).
A10: Imported Biodiesel - Refineries | B10: M€2022/PJ | C10: =C4*2 -> 63.0503 | D10: =(($I10-$C10)/($I$1-$C$1))*(D$1-C$1)+C10 -> 60.348145 | E10: =(($I10-$C10)/($I$1-$C$1))*(E$1-D$1)+D10 -> 55.844552 | F10: =(($I10-$C10)/($I$1-$C$1))*(F$1-E$1)+E10 -> 51.340959 | G10: =(($I10-$C10)/($I$1-$C$1))*(G$1-F$1)+F10 -> 46.837366 | H10: =(($I10-$C10)/($I$1-$C$1))*(H$1-G$1)+G10 -> 42.333773 | I10: =C10*0.6 -> 37.83018 | J10: 45629 | K10: TNO 2020; IEA Bioenergy 2020 | L10: Assumed 2x price of fossil equivalent in base year, then 40% decline by 2050.
A11: Imported Biokerosene - Refineries | B11: M€2022/PJ | C11: =C5*2 -> 60.748163 | D11: =(($I11-$C11)/($I$1-$C$1))*(D$1-C$1)+C11 -> 58.14467 | E11: =(($I11-$C11)/($I$1-$C$1))*(E$1-D$1)+D11 -> 53.805516 | F11: =(($I11-$C11)/($I$1-$C$1))*(F$1-E$1)+E11 -> 49.466361 | G11: =(($I11-$C11)/($I$1-$C$1))*(G$1-F$1)+F11 -> 45.127207 | H11: =(($I11-$C11)/($I$1-$C$1))*(H$1-G$1)+G11 -> 40.788052 | I11: =C11*0.6 -> 36.448898 | J11: 45629 | K11: TNO 2020; IEA Bioenergy 2020 | L11: Assumed 2x price of fossil equivalent in base year, then 40% decline by 2050.
A12: Imported Bio-LPG - Refineries | B12: M€2022/PJ | C12: =C2*2 -> 50.663929 | D12: =(($I12-$C12)/($I$1-$C$1))*(D$1-C$1)+C12 -> 48.492617 | E12: =(($I12-$C12)/($I$1-$C$1))*(E$1-D$1)+D12 -> 44.873765 | F12: =(($I12-$C12)/($I$1-$C$1))*(F$1-E$1)+E12 -> 41.254913 | G12: =(($I12-$C12)/($I$1-$C$1))*(G$1-F$1)+F12 -> 37.636061 | H12: =(($I12-$C12)/($I$1-$C$1))*(H$1-G$1)+G12 -> 34.017209 | I12: =C12*0.6 -> 30.398357 | J12: 45839 | K12: TNO 2020; IEA Bioenergy 2020 | L12: Assumed 2x price of fossil equivalent in base year, then 40% decline by 2050.
A13: Imported Natural Gas - Final Gas | B13: M€2022/PJ | C13: ='KEV2024'!$F$50 -> 26.878361 | D13: ='KEV2024'!$G$50 -> 15.52972 | E13: ='KEV2024'!$H$50 -> 6.8689145 | F13: =ROUND((E13+G13)/2,2) -> 5.95 | G13: =other_sources!L267 -> 5.028918 | H13: =ROUND((G13+I13)/2,2) -> 5.03 | I13: =other_sources!M267 -> 5.028918 | J13: 45853 | K13: KEV 2024; IEA 2024 | L13: KEV2024 prices used for 2022, 2025, 2030. Note that 2023 prices are used for 2025. IEA APS prices used for 2035-2050. No differentiation of prices for national & imported natural gas. Note that IEA's NZE includes declining global gas prices.
A14: Imported LNG - Final Gas | B14: M€2022/PJ | C14: =C13 -> 26.878361 | D14: =D13 -> 15.52972 | E14: =E13 -> 6.8689145 | F14: =F13 -> 5.95 | G14: =G13 -> 5.028918 | H14: =H13 -> 5.03 | I14: =I13 -> 5.028918 | J14: 45625 | K14: - | L14: Assumed equal to natural gas prices (import & domestic). Highly correlated and close together. (https://globallnghub.com/report-presentation/lng-markets-understanding-the-jkm-ttf-relationship) Average LNG NW Europe price reported by ACER from 1 January 2023-16 October 2024, not used because of volatility of LNG/TTF during the period 2020-2024.
A15: Imported Hydrogen (liquid) - Hydrogen Production | B15: M€2022/PJ | C15: =other_sources!I407 -> 41.250694 | D15: =ROUND((C15+E15)/2,2) -> 40.1 | E15: =other_sources!I403 -> 38.958989 | F15: =ROUND((E15+G15)/2,2) -> 38.58 | G15: =other_sources!I408 -> 38.195087 | H15: =ROUND((G15+I15)/2,2) -> 37.62 | I15: =other_sources!I405 -> 37.049235 | J15: 45628 | K15: IEA 2023 | L15: Assumed expensive liquid H2 import for 2022, less expensive liquid H2 import for 2030, high cost LOHC in 2040, low cost LOHC in 2050. These are based on 2030 costs for NW Europe in IEA NZE scenario, with imports from North Africa and Latin America.
A16: Imported Hydrogen (pipeline) - Hydrogen Production | B16: M€2022/PJ | C16: =other_sources!I410 -> 23.680954 | D16: =ROUND((C16+E16)/2,2) -> 22.34 | E16: =other_sources!I402 -> 21.007298 | F16: =ROUND((E16+G16)/2,2) -> 21.01 | G16: =other_sources!I402 -> 21.007298 | H16: =ROUND((G16+I16)/2,2) -> 21.01 | I16: =other_sources!I402 -> 21.007298 | J16: 45628 | K16: IEA 2023 | L16: 2022 value based on "domestic production" in NW Europe. 2030 to 2050 based on 2030 costs for NW Europe in IEA NZE scenario, with pipeline from North Africa. Assumes pipeline would be in place by 2030, volumes should be limited to reflect available pipeline infrastructure within Europe and from N Africa.
A17: Exported Hydrogen - Hydrogen Production | B17: M€2022/PJ | J17: 45582 | K17: - | L17: Should be set to zero, no assumed hydrogen exports as a baseline. No price needed.
A18: Imported Ammonia - Ammonia Production | B18: M€2022/PJ | C18: =other_sources!I369 -> 34.275681 | D18: =ROUND((C18+E18)/2,2) -> 30.38 | E18: =other_sources!I399 -> 26.481927 | F18: =ROUND((E18+G18)/2,2) -> 25.97 | G18: =ROUND((E18+I18)/2,2) -> 25.46 | H18: =ROUND((G18+I18)/2,2) -> 24.95 | I18: =other_sources!I400 -> 24.444856 | J18: 45628 | K18: Platts 2024; IEA 2023 | L18: Platts Ammonia price data for base year. Used current (2024) values, average of all ammonia types, for 2022. For 2030, IEA source used - import from NA. For 2050, import from Latin America. Based on 2030 costs for NW Europe in IEA NZE scenario.
A19: Imported Coal | B19: M€2022/PJ | C19: ='KEV2024'!F52 -> 11.963684 | D19: ='KEV2024'!G52 -> 8.0823362 | E19: ='KEV2024'!H52 -> 3.0137525 | F19: ='KEV2024'!I52 -> 3.0594154 | G19: =other_sources!L271 -> 2.2584921 | H19: =(G19+I19)/2 -> 2.1920659 | I19: =other_sources!M271 -> 2.1256396 | J19: 45853 | K19: KEV 2024; IEA 2024 | L19: KEV2024 prices used for 2022, 2025, 2030. Note that 2023 prices are used for 2025. Note that KEV draws on CPB & CBS data and EC research. IEA APS prices used for 2035-2050. Steenkool & bruinkool NCV used to calculate price.
A20: Imported Crude Oil | B20: M€2022/PJ | C20: ='KEV2024'!F48 -> 14.70203 | D20: =ROUND((C20+E20)/2,2) -> 13.65 | E20: ='KEV2024'!H48 -> 12.60174 | F20: ='KEV2024'!I48 -> 12.60174 | G20: =other_sources!L263 -> 9.4513053 | H20: =ROUND((G20+I20)/2,2) -> 9.08 | I20: =other_sources!M263 -> 8.7012017 | J20: 45853 | K20: KEV 2024; IEA 2024 | L20: KEV2024 prices used for 2022. Note that KEV draws on CPB & CBS data and EC research. IEA APS prices used for 2030-2050.
A21: National Natural Gas | B21: M€2022/PJ | C21: ='KEV2024'!$F$50 -> 26.878361 | D21: ='KEV2024'!$G$50 -> 15.52972 | E21: ='KEV2024'!$H$50 -> 6.8689145 | F21: =ROUND((E21+G21)/2,2) -> 5.95 | G21: =other_sources!L267 -> 5.028918 | H21: =ROUND((G21+I21)/2,2) -> 5.03 | I21: =other_sources!M267 -> 5.028918 | J21: 45853 | K21: KEV 2024; IEA 2024 | L21: KEV2024 prices used for 2022, 2025, 2030. Note that 2023 prices are used for 2025. IEA APS used for 2035-2050. No differentiation of prices for national & imported natural gas.
A22: Municipal Waste NL | B22: M€2022/PJ | C22: =33.58/9.5 -> 3.5347368 | D22: =39.23/9.5 -> 4.1294737 | E22: =D22 -> 4.1294737 | F22: =E22 -> 4.1294737 | G22: =F22 -> 4.1294737 | H22: =G22 -> 4.1294737 | I22: =H22 -> 4.1294737 | J22: 45582 | K22: CE Delft 2024 | L22: Updated based on 2022 tariff per tonne of municipal waste for 2022, and 2024 used for 2025-2050. Assumed 9.5 MJ/kg municipal waste.
A23: Imported plastic waste | B23: M€2022/Mt | C23: ='average_yearly price of plastic'!$A$15 -> 466.69121 | D23: =C23 -> 466.69121 | E23: =D23 -> 466.69121 | F23: =E23 -> 466.69121 | G23: =F23 -> 466.69121 | H23: =G23 -> 466.69121 | I23: =H23 -> 466.69121 | J23: 45582 | K23: EEA 2024 | L23: Assumed 2022 price will remain constant until 2050. Note increasing trend in recent years. Price given in mass terms (not energy).
A24: Wood (crops, and others) | B24: M€2022/PJ | C24: 10.6 | D24: =C24 -> 10.6 | E24: =D24 -> 10.6 | F24: =E24 -> 10.6 | G24: =F24 -> 10.6 | H24: =G24 -> 10.6 | I24: =H24 -> 10.6 | J24: 45625 | K24: SDE++ 2022 | L24: Assumed equal to Houtpellets, ketels price for woody biomass in 2022.
A25: Imported Wood EU | B25: M€2022/PJ | C25: =other_sources!F178 -> 11.167017 | D25: =C25 -> 11.167017 | E25: =D25 -> 11.167017 | F25: =E25 -> 11.167017 | G25: =F25 -> 11.167017 | H25: =G25 -> 11.167017 | I25: =H25 -> 11.167017 | J25: 45582 | K25: TNO 2024 | L25: Assumed equal to 2030/2050 price for cheap imported woody biomass
A26: Imported Wood America | B26: M€2022/PJ | C26: =other_sources!F179 -> 14.620734 | D26: =C26 -> 14.620734 | E26: =D26 -> 14.620734 | F26: =E26 -> 14.620734 | G26: =F26 -> 14.620734 | H26: =G26 -> 14.620734 | I26: =H26 -> 14.620734 | J26: 45582 | K26: TNO 2024 | L26: Assumed equal to 2030/2050 price for expensive imported woody biomass
A27: Grasscrops | B27: M€2022/PJ | C27: ='[1]COST - NUTS0 EnergyCom'!$E$3303*Conversions!$AA$2/Conversions!$Q$2 -> 9.5931288 | D27: =ROUND((C27+E27)/2,2) -> 9.17 | E27: ='Enspreso_COST - NUTS0 EnergyCom'!E6111*Conversions!$AA$2/Conversions!$Q$2 -> 8.7472214 | F27: =ROUND((E27+G27)/2,2) -> 8.62 | G27: ='Enspreso_COST - NUTS0 EnergyCom'!E8383*Conversions!$AA$2/Conversions!$Q$2 -> 8.4831259 | H27: =ROUND((G27+I27)/2,2) -> 8.36 | I27: ='Enspreso_COST - NUTS0 EnergyCom'!E10655*Conversions!$AA$2/Conversions!$Q$2 -> 8.2424305 | J27: 45834 | K27: JRC 2019 | L27: Based on ENSPRESO costs (ENS Med scenario) for NL. Original source in EUR2010. MINBIOCRP31
A28: Dry organic matter | B28: M€2022/PJ | C28: ='Enspreso_COST - NUTS0 EnergyCom'!$E$3708*Conversions!$AA$2/Conversions!$Q$2 -> 26.799359 | D28: =ROUND((C28+E28)/2,2) -> 32.61 | E28: ='Enspreso_COST - NUTS0 EnergyCom'!$E$5947*Conversions!$AA$2/Conversions!$Q$2 -> 38.426321 | F28: =ROUND((E28+G28)/2,2) -> 38.4 | G28: ='Enspreso_COST - NUTS0 EnergyCom'!$E$8219*Conversions!$AA$2/Conversions!$Q$2 -> 38.376558 | H28: =ROUND((G28+I28)/2,2) -> 38.35 | I28: ='Enspreso_COST - NUTS0 EnergyCom'!$E$10491*Conversions!$AA$2/Conversions!$Q$2 -> 38.325672 | J28: 45834 | K28: JRC 2019 | L28: Based on ENSPRESO costs (ENS Med scenario) for NL. Original source in EUR2010. MINBIORPS1
A29: Wet organic matter | B29: M€2022/PJ | C29: ='Enspreso_COST - NUTS0 EnergyCom'!$E$3709*Conversions!$AA$2/Conversions!$Q$2 -> 8.5386322 | D29: =ROUND((C29+E29)/2,2) -> 8.11 | E29: ='Enspreso_COST - NUTS0 EnergyCom'!$E$5948*Conversions!$AA$2/Conversions!$Q$2 -> 7.684769 | F29: =ROUND((E29+G29)/2,2) -> 7.3 | G29: ='Enspreso_COST - NUTS0 EnergyCom'!$E$8220*Conversions!$AA$2/Conversions!$Q$2 -> 6.9162921 | H29: =ROUND((G29+I29)/2,2) -> 6.57 | I29: ='Enspreso_COST - NUTS0 EnergyCom'!$E$10492*Conversions!$AA$2/Conversions!$Q$2 -> 6.2246629 | J29: 45834 | K29: JRC 2019 | L29: Based on ENSPRESO costs (ENS Med scenario) for NL. Original source in EUR2010. MINBIOSLU1
A30: Manure | B30: M€2022/PJ | C30: ='Enspreso_COST - NUTS0 EnergyCom'!$E$3706*Conversions!$AA$2/Conversions!$Q$2 -> 6.977354 | D30: =ROUND((C30+E30)/2,2) -> 7 | E30: ='Enspreso_COST - NUTS0 EnergyCom'!$E$5945*Conversions!$AA$2/Conversions!$Q$2 -> 7.0240302 | F30: =ROUND((E30+G30)/2,2) -> 7.04 | G30: ='Enspreso_COST - NUTS0 EnergyCom'!$E$8217*Conversions!$AA$2/Conversions!$Q$2 -> 7.0605801 | H30: =ROUND((G30+I30)/2,2) -> 7.07 | I30: ='Enspreso_COST - NUTS0 EnergyCom'!$E$10489*Conversions!$AA$2/Conversions!$Q$2 -> 7.0787377 | J30: 45834 | K30: JRC 2019 | L30: Based on ENSPRESO costs (ENS Med scenario) for NL. Original source in EUR2010. MINBIOGAS1
A31: Sugars | B31: M€2022/PJ | C31: ='Enspreso_COST - NUTS0 EnergyCom'!$E$3701*Conversions!$AA$2/Conversions!$Q$2 -> 4.3284907 | D31: =ROUND((C31+E31)/2,2) -> 4.47 | E31: ='Enspreso_COST - NUTS0 EnergyCom'!$E$5940*Conversions!$AA$2/Conversions!$Q$2 -> 4.6157889 | F31: =ROUND((E31+G31)/2,2) -> 4.63 | G31: ='Enspreso_COST - NUTS0 EnergyCom'!$E$8212*Conversions!$AA$2/Conversions!$Q$2 -> 4.6444136 | H31: =ROUND((G31+I31)/2,2) -> 4.66 | I31: ='Enspreso_COST - NUTS0 EnergyCom'!$E$10484*Conversions!$AA$2/Conversions!$Q$2 -> 4.6730383 | J31: 45834 | K31: JRC 2019 | L31: Based on ENSPRESO costs (ENS Med scenario) for NL. Original source in EUR2010. MINBIOCRP21
A32: Starch | B32: M€2022/PJ | C32: 16 | D32: =ROUND((C32+E32)/2,2) -> 18.5 | E32: 21 | F32: =ROUND((E32+G32)/2,2) -> 21.25 | G32: =ROUND((E32+I32)/2,2) -> 21.5 | H32: =ROUND((G32+I32)/2,2) -> 21.75 | I32: 22 | K32: EU 2017 | L32: Not updated, no updated source available. Uptake mainly driven by (small) potentials. Currently based on Heat Roadmap Europe prices.
A33: Vegetable Oil | B33: M€2022/PJ | C33: ='Enspreso_COST - NUTS0 EnergyCom'!$E$3708*Conversions!$AA$2/Conversions!$Q$2 -> 26.799359 | D33: =ROUND((C33+E33)/2,2) -> 32.61 | E33: ='Enspreso_COST - NUTS0 EnergyCom'!$E$5947*Conversions!$AA$2/Conversions!$Q$2 -> 38.426321 | F33: =ROUND((E33+G33)/2,2) -> 38.4 | G33: ='Enspreso_COST - NUTS0 EnergyCom'!$E$8219*Conversions!$AA$2/Conversions!$Q$2 -> 38.376558 | H33: =ROUND((G33+I33)/2,2) -> 38.35 | I33: ='Enspreso_COST - NUTS0 EnergyCom'!$E$10491*Conversions!$AA$2/Conversions!$Q$2 -> 38.325672 | J33: 45834 | K33: JRC 2019 | L33: Based on ENSPRESO costs (ENS Med scenario) for NL. Original source in EUR2010. MINBIORPS1
A34: Imported Vegetable Oil | B34: M€2022/PJ | C34: =C33*1.1 -> 29.479295 | D34: =D33*1.1 -> 35.871 | E34: =E33*1.1 -> 42.268953 | F34: =F33*1.1 -> 42.24 | G34: =G33*1.1 -> 42.214214 | H34: =H33*1.1 -> 42.185 | I34: =I33*1.1 -> 42.158239 | J34: 45834 | K34: TNO 2024 | L34: Assumed 10% markup for imported vegetable oil from rest of Europe
A35: Imported DRI briquettes | B35: M€2022/Mt | C35: =441/Conversions!AC4 -> 418.80342 | D35: =C35 -> 418.80342 | E35: =D35 -> 418.80342 | F35: =E35 -> 418.80342 | G35: =F35 -> 418.80342 | H35: =G35 -> 418.80342 | I35: =H35 -> 418.80342 | J35: 45748 | K35: Steel on the net.com 2025 | L35: Average of 2022 values. Future prices could be constructed from some relation to iron ore, gas, and coal prices (right now much of global DRI exports come from coal) https://www.steelonthenet.com/files/dri.html
A36: Imported or purchased steel scrap | B36: M€2022/Mt | C36: =Steel_scrap!F36 -> 422.17711 | D36: =C36 -> 422.17711 | E36: =D36 -> 422.17711 | F36: =E36 -> 422.17711 | G36: =F36 -> 422.17711 | H36: =G36 -> 422.17711 | I36: =H36 -> 422.17711 | J36: 45748 | K36: Investing.com (in range of news articles) | L36: https://www.investing.com/commodities/steel-scrap-historical-data
A37: Ethylene imports - Petrochemical industry | B37: M€2022/Mt | C37: =AVERAGE(olefins!T20:T21) -> 1146.9706 | D37: =C37 -> 1146.9706 | E37: =D37 -> 1146.9706 | F37: =E37 -> 1146.9706 | G37: =F37 -> 1146.9706 | H37: =G37 -> 1146.9706 | I37: =H37 -> 1146.9706 | J37: 45748 | K37: CBS 2025 | L37: invoerwaarde & hoeveelheid, normal portland cement, total of EU & non-EU countries, https://opendata.cbs.nl/#/CBS/nl/dataset/81261ned/table?searchKeywords=cement
A38: Propylene imports - Petrochemical industry | B38: M€2022/Mt | C38: =AVERAGE(olefins!T35:T36) -> 1138.7412 | D38: =C38 -> 1138.7412 | E38: =D38 -> 1138.7412 | F38: =E38 -> 1138.7412 | G38: =F38 -> 1138.7412 | H38: =G38 -> 1138.7412 | I38: =H38 -> 1138.7412 | J38: 45748 | K38: CBS 2025 | L38: invoerwaarde & hoeveelheid, normal portland cement, total of EU & non-EU countries, https://opendata.cbs.nl/#/CBS/nl/dataset/81261ned/table?searchKeywords=cement
A39: Butadiene imports - Petrochemical industry | B39: M€2022/Mt | C39: =AVERAGE(olefins!T50:T51) -> 1025.3758 | D39: =C39 -> 1025.3758 | E39: =D39 -> 1025.3758 | F39: =E39 -> 1025.3758 | G39: =F39 -> 1025.3758 | H39: =G39 -> 1025.3758 | I39: =H39 -> 1025.3758 | J39: 45748 | K39: CBS 2025 | L39: invoerwaarde & hoeveelheid, normal portland cement, total of EU & non-EU countries, https://opendata.cbs.nl/#/CBS/nl/dataset/81261ned/table?searchKeywords=cement
A40: Imported aromatics | B40: M€2022/Mt | C40: =C7*40 -> 705.08159 | D40: =D7*40 -> 654.6282 | E40: =E7*40 -> 604.35565 | F40: =F7*40 -> 604.35565 | G40: =G7*40 -> 453.26673 | H40: =H7*40 -> 435.45964 | I40: =I7*40 -> 417.29318 | J40: 45582 | L40: Assumed equal to "other oil product imports." Converted to mass terms with NCV 40 MJ/kg.
...

Sheet Commodity_prices_MEUR2019
A1: Name | B1: Unit | C1: 2022 | D1: 2025 | E1: 2030 | F1: 2035 | G1: 2040 | H1: 2045 | I1: 2050 | J1: Updated | K1: Source | L1: Notes
A2: Imported LPG - Refineries | B2: M€2019/PJ | C2: =Commodity_prices_MEUR2022!C2*(Conversions!$Z$2/Conversions!$AC$2) -> 23.181827 | D2: =Commodity_prices_MEUR2022!D2*(Conversions!$Z$2/Conversions!$AC$2) -> 21.52301 | E2: =Commodity_prices_MEUR2022!E2*(Conversions!$Z$2/Conversions!$AC$2) -> 19.870138 | F2: =Commodity_prices_MEUR2022!F2*(Conversions!$Z$2/Conversions!$AC$2) -> 19.870138 | G2: =Commodity_prices_MEUR2022!G2*(Conversions!$Z$2/Conversions!$AC$2) -> 14.902603 | H2: =Commodity_prices_MEUR2022!H2*(Conversions!$Z$2/Conversions!$AC$2) -> 14.317138 | I2: =Commodity_prices_MEUR2022!I2*(Conversions!$Z$2/Conversions!$AC$2) -> 13.719857 | J2: 45582 | K2: EC Weekly Oil Bulletin | L2: Average of weekly 2022 fuel oil prices for NL reported in oil bulletin. Assumed 45.2 MJ/kg per RVO NCV for LPG, and 1915 l/t as per IEA statistics manual. Future years assume constant ratio for refined products to crude oil.
A3: Imported Naphtha - Refineries | B3: M€2019/PJ | C3: =Commodity_prices_MEUR2022!C3*(Conversions!$Z$2/Conversions!$AC$2) -> 15.208573 | D3: =Commodity_prices_MEUR2022!D3*(Conversions!$Z$2/Conversions!$AC$2) -> 14.120296 | E3: =Commodity_prices_MEUR2022!E3*(Conversions!$Z$2/Conversions!$AC$2) -> 13.03592 | F3: =Commodity_prices_MEUR2022!F3*(Conversions!$Z$2/Conversions!$AC$2) -> 13.03592 | G3: =Commodity_prices_MEUR2022!G3*(Conversions!$Z$2/Conversions!$AC$2) -> 9.77694 | H3: =Commodity_prices_MEUR2022!H3*(Conversions!$Z$2/Conversions!$AC$2) -> 9.3928418 | I3: =Commodity_prices_MEUR2022!I3*(Conversions!$Z$2/Conversions!$AC$2) -> 9.0009924 | J3: 45582 | K3: BASF key prices | L3: Base year prices reported by BASF (annual average price for 2022). Projections are based on ratio of naphtha to crude oil price.
A4: Imported Road Fuel - Refineries | B4: M€2019/PJ | C4: =Commodity_prices_MEUR2022!C4*(Conversions!$Z$2/Conversions!$AC$2) -> 28.849345 | D4: =Commodity_prices_MEUR2022!D4*(Conversions!$Z$2/Conversions!$AC$2) -> 26.784978 | E4: =Commodity_prices_MEUR2022!E4*(Conversions!$Z$2/Conversions!$AC$2) -> 24.72801 | F4: =Commodity_prices_MEUR2022!F4*(Conversions!$Z$2/Conversions!$AC$2) -> 24.72801 | G4: =Commodity_prices_MEUR2022!G4*(Conversions!$Z$2/Conversions!$AC$2) -> 18.546008 | H4: =Commodity_prices_MEUR2022!H4*(Conversions!$Z$2/Conversions!$AC$2) -> 17.817407 | I4: =Commodity_prices_MEUR2022!I4*(Conversions!$Z$2/Conversions!$AC$2) -> 17.074102 | J4: 45582 | K4: EC Weekly Oil Bulletin | L4: Average of weekly 2022 fuel oil prices for NL reported in oil bulletin. Assumed 43.3 MJ/kg per RVO NCV for gasoline, and 1350 l/t as per IEA statistics manual. Future years assume constant ratio for refined products to crude oil.
A5: Imported Kerosene - Refineries | B5: M€2019/PJ | C5: =Commodity_prices_MEUR2022!C5*(Conversions!$Z$2/Conversions!$AC$2) -> 27.795978 | D5: =Commodity_prices_MEUR2022!D5*(Conversions!$Z$2/Conversions!$AC$2) -> 25.806986 | E5: =Commodity_prices_MEUR2022!E5*(Conversions!$Z$2/Conversions!$AC$2) -> 23.825124 | F5: =Commodity_prices_MEUR2022!F5*(Conversions!$Z$2/Conversions!$AC$2) -> 23.825124 | G5: =Commodity_prices_MEUR2022!G5*(Conversions!$Z$2/Conversions!$AC$2) -> 17.868843 | H5: =Commodity_prices_MEUR2022!H5*(Conversions!$Z$2/Conversions!$AC$2) -> 17.166845 | I5: =Commodity_prices_MEUR2022!I5*(Conversions!$Z$2/Conversions!$AC$2) -> 16.450681 | J5: 45582 | K5: EC Weekly Oil Bulletin; IEA 2024 | L5: Used gas/diesel oil as a proxy. Average of weekly 2022 fuel oil prices for NL reported in oil bulletin. Assumed 43.2 MJ/kg per RVO NCV for gasoline, and 1185 l/t as per IEA statistics manual. Future years assume constant ratio for refined products to crude oil. Well aligned with prices for BE in IEA 2024 (End Use price explorer) - there NL data is only available for 2010.
A6: Imported Fuel Oil - Refineries | B6: M€2019/PJ | C6: =Commodity_prices_MEUR2022!C6*(Conversions!$Z$2/Conversions!$AC$2) -> 16.130885 | D6: =Commodity_prices_MEUR2022!D6*(Conversions!$Z$2/Conversions!$AC$2) -> 14.97661 | E6: =Commodity_prices_MEUR2022!E6*(Conversions!$Z$2/Conversions!$AC$2) -> 13.826472 | F6: =Commodity_prices_MEUR2022!F6*(Conversions!$Z$2/Conversions!$AC$2) -> 13.826472 | G6: =Commodity_prices_MEUR2022!G6*(Conversions!$Z$2/Conversions!$AC$2) -> 10.369854 | H6: =Commodity_prices_MEUR2022!H6*(Conversions!$Z$2/Conversions!$AC$2) -> 9.9624628 | I6: =Commodity_prices_MEUR2022!I6*(Conversions!$Z$2/Conversions!$AC$2) -> 9.54685 | J6: 45582 | K6: EC Weekly Oil Bulletin | L6: Average of weekly 2022 fuel oil prices for NL reported in oil bulletin. Assumed 41 MJ/kg per RVO NCV for residual fuel oil. Future years assume constant ratio for refined products to crude oil.
A7: Imported Other Oil Products - Refineries | B7: M€2019/PJ | C7: =Commodity_prices_MEUR2022!C7*(Conversions!$Z$2/Conversions!$AC$2) -> 16.130885 | D7: =Commodity_prices_MEUR2022!D7*(Conversions!$Z$2/Conversions!$AC$2) -> 14.97661 | E7: =Commodity_prices_MEUR2022!E7*(Conversions!$Z$2/Conversions!$AC$2) -> 13.826472 | F7: =Commodity_prices_MEUR2022!F7*(Conversions!$Z$2/Conversions!$AC$2) -> 13.826472 | G7: =Commodity_prices_MEUR2022!G7*(Conversions!$Z$2/Conversions!$AC$2) -> 10.369854 | H7: =Commodity_prices_MEUR2022!H7*(Conversions!$Z$2/Conversions!$AC$2) -> 9.9624628 | I7: =Commodity_prices_MEUR2022!I7*(Conversions!$Z$2/Conversions!$AC$2) -> 9.54685 | J7: 45579 | K7: - | L7: Assumed equal to fuel oil.
A8: Imported Bionaphtha - Refineries | B8: M€2019/PJ | C8: =Commodity_prices_MEUR2022!C8*(Conversions!$Z$2/Conversions!$AC$2) -> 30.417147 | D8: =Commodity_prices_MEUR2022!D8*(Conversions!$Z$2/Conversions!$AC$2) -> 29.113555 | E8: =Commodity_prices_MEUR2022!E8*(Conversions!$Z$2/Conversions!$AC$2) -> 26.940901 | F8: =Commodity_prices_MEUR2022!F8*(Conversions!$Z$2/Conversions!$AC$2) -> 24.768248 | G8: =Commodity_prices_MEUR2022!G8*(Conversions!$Z$2/Conversions!$AC$2) -> 22.595595 | H8: =Commodity_prices_MEUR2022!H8*(Conversions!$Z$2/Conversions!$AC$2) -> 20.422941 | I8: =Commodity_prices_MEUR2022!I8*(Conversions!$Z$2/Conversions!$AC$2) -> 18.250288 | J8: 45629 | K8: TNO 2020; IEA Bioenergy 2020 | L8: Assumed 2x price of fossil equivalent in base year, then 40% decline by 2050.
A9: Imported Bioethanol - Refineries | B9: M€2019/PJ | C9: =Commodity_prices_MEUR2022!C9*(Conversions!$Z$2/Conversions!$AC$2) -> 38.23209 | D9: =Commodity_prices_MEUR2022!D9*(Conversions!$Z$2/Conversions!$AC$2) -> 34.811225 | E9: =Commodity_prices_MEUR2022!E9*(Conversions!$Z$2/Conversions!$AC$2) -> 31.38867 | F9: =Commodity_prices_MEUR2022!F9*(Conversions!$Z$2/Conversions!$AC$2) -> 31.38867 | G9: =Commodity_prices_MEUR2022!G9*(Conversions!$Z$2/Conversions!$AC$2) -> 31.38867 | H9: =Commodity_prices_MEUR2022!H9*(Conversions!$Z$2/Conversions!$AC$2) -> 31.38867 | I9: =Commodity_prices_MEUR2022!I9*(Conversions!$Z$2/Conversions!$AC$2) -> 31.38867 | J9: 45625 | K9: TNO 2024; IEA 2021 | L9: 2022 price from IEA Renewables Market Report. European ethanol price of $1.3/liter. Ethanol market currently at a high point (see market report) due to supply shocks i.e. high price of key feedstocks like corn. We take TNO 2030 value as the longer term stable value, as price shock effects dissipate. Demand pressures are mixed (US & Europe loosening or keeping stable their blending requirements, while new requirements are implemented elsewhere i.e. India). Assumed equal to 2030/2050 price for bioethanol. Note TNO assumes significant price increase to 2050 (~4x).
A10: Imported Biodiesel - Refineries | B10: M€2019/PJ | C10: =Commodity_prices_MEUR2022!C10*(Conversions!$Z$2/Conversions!$AC$2) -> 57.698691 | D10: =Commodity_prices_MEUR2022!D10*(Conversions!$Z$2/Conversions!$AC$2) -> 55.22589 | E10: =Commodity_prices_MEUR2022!E10*(Conversions!$Z$2/Conversions!$AC$2) -> 51.104555 | F10: =Commodity_prices_MEUR2022!F10*(Conversions!$Z$2/Conversions!$AC$2) -> 46.98322 | G10: =Commodity_prices_MEUR2022!G10*(Conversions!$Z$2/Conversions!$AC$2) -> 42.861885 | H10: =Commodity_prices_MEUR2022!H10*(Conversions!$Z$2/Conversions!$AC$2) -> 38.74055 | I10: =Commodity_prices_MEUR2022!I10*(Conversions!$Z$2/Conversions!$AC$2) -> 34.619215 | J10: 45629 | K10: TNO 2020; IEA Bioenergy 2020 | L10: Assumed 2x price of fossil equivalent in base year, then 40% decline by 2050.
A11: Imported Biokerosene - Refineries | B11: M€2019/PJ | C11: =Commodity_prices_MEUR2022!C11*(Conversions!$Z$2/Conversions!$AC$2) -> 55.591955 | D11: =Commodity_prices_MEUR2022!D11*(Conversions!$Z$2/Conversions!$AC$2) -> 53.209443 | E11: =Commodity_prices_MEUR2022!E11*(Conversions!$Z$2/Conversions!$AC$2) -> 49.238589 | F11: =Commodity_prices_MEUR2022!F11*(Conversions!$Z$2/Conversions!$AC$2) -> 45.267735 | G11: =Commodity_prices_MEUR2022!G11*(Conversions!$Z$2/Conversions!$AC$2) -> 41.296881 | H11: =Commodity_prices_MEUR2022!H11*(Conversions!$Z$2/Conversions!$AC$2) -> 37.326027 | I11: =Commodity_prices_MEUR2022!I11*(Conversions!$Z$2/Conversions!$AC$2) -> 33.355173 | J11: 45629 | K11: TNO 2020; IEA Bioenergy 2020 | L11: Assumed 2x price of fossil equivalent in base year, then 40% decline by 2050.
A12: Imported Bio-LPG - Refineries | B12: M€2019/PJ | C12: =Commodity_prices_MEUR2022!C12*(Conversions!$Z$2/Conversions!$AC$2) -> 46.363655 | D12: =Commodity_prices_MEUR2022!D12*(Conversions!$Z$2/Conversions!$AC$2) -> 44.376641 | E12: =Commodity_prices_MEUR2022!E12*(Conversions!$Z$2/Conversions!$AC$2) -> 41.064951 | F12: =Commodity_prices_MEUR2022!F12*(Conversions!$Z$2/Conversions!$AC$2) -> 37.753262 | G12: =Commodity_prices_MEUR2022!G12*(Conversions!$Z$2/Conversions!$AC$2) -> 34.441572 | H12: =Commodity_prices_MEUR2022!H12*(Conversions!$Z$2/Conversions!$AC$2) -> 31.129882 | I12: =Commodity_prices_MEUR2022!I12*(Conversions!$Z$2/Conversions!$AC$2) -> 27.818193 | J12: 45839 | K12: TNO 2020; IEA Bioenergy 2020 | L12: Assumed 2x price of fossil equivalent in base year, then 40% decline by 2050.
A13: Imported Natural Gas - Final Gas | B13: M€2019/PJ | C13: =Commodity_prices_MEUR2022!C13*(Conversions!$Z$2/Conversions!$AC$2) -> 24.596969 | D13: =Commodity_prices_MEUR2022!D13*(Conversions!$Z$2/Conversions!$AC$2) -> 14.211582 | E13: =Commodity_prices_MEUR2022!E13*(Conversions!$Z$2/Conversions!$AC$2) -> 6.285892 | F13: =Commodity_prices_MEUR2022!F13*(Conversions!$Z$2/Conversions!$AC$2) -> 5.4449734 | G13: =Commodity_prices_MEUR2022!G13*(Conversions!$Z$2/Conversions!$AC$2) -> 4.6020714 | H13: =Commodity_prices_MEUR2022!H13*(Conversions!$Z$2/Conversions!$AC$2) -> 4.6030616 | I13: =Commodity_prices_MEUR2022!I13*(Conversions!$Z$2/Conversions!$AC$2) -> 4.6020714 | J13: 45853 | K13: KEV 2024; IEA 2024 | L13: KEV2024 prices used for 2022, 2025, 2030. Note that 2023 prices are used for 2025. IEA APS prices used for 2035-2050. No differentiation of prices for national & imported natural gas. Note that IEA's NZE includes declining global gas prices.
... A31: Sugars | B31: M€2019/PJ | C31: =Commodity_prices_MEUR2022!C31*(Conversions!$Z$2/Conversions!$AC$2) -> 3.9610952 | D31: =Commodity_prices_MEUR2022!D31*(Conversions!$Z$2/Conversions!$AC$2) -> 4.0905935 | E31: =Commodity_prices_MEUR2022!E31*(Conversions!$Z$2/Conversions!$AC$2) -> 4.224008 | F31: =Commodity_prices_MEUR2022!F31*(Conversions!$Z$2/Conversions!$AC$2) -> 4.237013 | G31: =Commodity_prices_MEUR2022!G31*(Conversions!$Z$2/Conversions!$AC$2) -> 4.2502031 | H31: =Commodity_prices_MEUR2022!H31*(Conversions!$Z$2/Conversions!$AC$2) -> 4.2644666 | I31: =Commodity_prices_MEUR2022!I31*(Conversions!$Z$2/Conversions!$AC$2) -> 4.2763983 | J31: 45834 | K31: JRC 2019 | L31: Based on ENSPRESO costs (ENS Med scenario) for NL. Original source in EUR2010. MINBIOCRP21
A32: Starch | B32: M€2019/PJ | C32: =Commodity_prices_MEUR2022!C32*(Conversions!$Z$2/Conversions!$AC$2) -> 14.641945 | D32: =Commodity_prices_MEUR2022!D32*(Conversions!$Z$2/Conversions!$AC$2) -> 16.929749 | E32: =Commodity_prices_MEUR2022!E32*(Conversions!$Z$2/Conversions!$AC$2) -> 19.217553 | F32: =Commodity_prices_MEUR2022!F32*(Conversions!$Z$2/Conversions!$AC$2) -> 19.446334 | G32: =Commodity_prices_MEUR2022!G32*(Conversions!$Z$2/Conversions!$AC$2) -> 19.675114 | H32: =Commodity_prices_MEUR2022!H32*(Conversions!$Z$2/Conversions!$AC$2) -> 19.903895 | I32: =Commodity_prices_MEUR2022!I32*(Conversions!$Z$2/Conversions!$AC$2) -> 20.132675 | K32: EU 2017 | L32: Not updated, no updated source available. Uptake mainly driven by (small) potentials. Currently based on Heat Roadmap Europe prices.
A33: Vegetable Oil | B33: M€2019/PJ | C33: =Commodity_prices_MEUR2022!C33*(Conversions!$Z$2/Conversions!$AC$2) -> 24.524672 | D33: =Commodity_prices_MEUR2022!D33*(Conversions!$Z$2/Conversions!$AC$2) -> 29.842115 | E33: =Commodity_prices_MEUR2022!E33*(Conversions!$Z$2/Conversions!$AC$2) -> 35.164756 | F33: =Commodity_prices_MEUR2022!F33*(Conversions!$Z$2/Conversions!$AC$2) -> 35.140669 | G33: =Commodity_prices_MEUR2022!G33*(Conversions!$Z$2/Conversions!$AC$2) -> 35.119217 | H33: =Commodity_prices_MEUR2022!H33*(Conversions!$Z$2/Conversions!$AC$2) -> 35.094913 | I33: =Commodity_prices_MEUR2022!I33*(Conversions!$Z$2/Conversions!$AC$2) -> 35.07265 | J33: 45582 | K33: TNO 2024 | L33: Based on ENSPRESO costs (ENS Med scenario) for NL. Original source in EUR2010. MINBIORPS1
A34: Imported Vegetable Oil | B34: M€2019/PJ | C34: =Commodity_prices_MEUR2022!C34*(Conversions!$Z$2/Conversions!$AC$2) -> 26.97714 | D34: =Commodity_prices_MEUR2022!D34*(Conversions!$Z$2/Conversions!$AC$2) -> 32.826326 | E34: =Commodity_prices_MEUR2022!E34*(Conversions!$Z$2/Conversions!$AC$2) -> 38.681231 | F34: =Commodity_prices_MEUR2022!F34*(Conversions!$Z$2/Conversions!$AC$2) -> 38.654736 | G34: =Commodity_prices_MEUR2022!G34*(Conversions!$Z$2/Conversions!$AC$2) -> 38.631139 | H34: =Commodity_prices_MEUR2022!H34*(Conversions!$Z$2/Conversions!$AC$2) -> 38.604404 | I34: =Commodity_prices_MEUR2022!I34*(Conversions!$Z$2/Conversions!$AC$2) -> 38.579915 | J34: 45582 | K34: TNO 2024 | L34: Assumed 10% markup for imported vegetable oil from rest of Europe
A35: Imported DRI briquettes | B35: M€2019/Mt | C35: =Commodity_prices_MEUR2022!C35*(Conversions!$Z$2/Conversions!$AC$2) -> 383.25605 | D35: =Commodity_prices_MEUR2022!D35*(Conversions!$Z$2/Conversions!$AC$2) -> 383.25605 | E35: =Commodity_prices_MEUR2022!E35*(Conversions!$Z$2/Conversions!$AC$2) -> 383.25605 | F35: =Commodity_prices_MEUR2022!F35*(Conversions!$Z$2/Conversions!$AC$2) -> 383.25605 | G35: =Commodity_prices_MEUR2022!G35*(Conversions!$Z$2/Conversions!$AC$2) -> 383.25605 | H35: =Commodity_prices_MEUR2022!H35*(Conversions!$Z$2/Conversions!$AC$2) -> 383.25605 | I35: =Commodity_prices_MEUR2022!I35*(Conversions!$Z$2/Conversions!$AC$2) -> 383.25605 | J35: 45748 | K35: Steel on the net.com 2025 | L35: Average of 2022 values. Future prices could be constructed from some relation to iron ore, gas, and coal prices (right now much of global DRI exports come from coal) https://www.steelonthenet.com/files/dri.html
A36: Imported or purchased steel scrap | B36: M€2019/Mt | C36: =Commodity_prices_MEUR2022!C36*(Conversions!$Z$2/Conversions!$AC$2) -> 386.34339 | D36: =Commodity_prices_MEUR2022!D36*(Conversions!$Z$2/Conversions!$AC$2) -> 386.34339 | E36: =Commodity_prices_MEUR2022!E36*(Conversions!$Z$2/Conversions!$AC$2) -> 386.34339 | F36: =Commodity_prices_MEUR2022!F36*(Conversions!$Z$2/Conversions!$AC$2) -> 386.34339 | G36: =Commodity_prices_MEUR2022!G36*(Conversions!$Z$2/Conversions!$AC$2) -> 386.34339 | H36: =Commodity_prices_MEUR2022!H36*(Conversions!$Z$2/Conversions!$AC$2) -> 386.34339 | I36: =Commodity_prices_MEUR2022!I36*(Conversions!$Z$2/Conversions!$AC$2) -> 386.34339 | J36: 45748 | K36: Investing.com (in range of news articles) | L36: https://www.investing.com/commodities/steel-scrap-historical-data
A37: Ethylene imports - Petrochemical industry | B37: M€2019/Mt | C37: =Commodity_prices_MEUR2022!C37*(Conversions!$Z$2/Conversions!$AC$2) -> 1049.6176 | D37: =Commodity_prices_MEUR2022!D37*(Conversions!$Z$2/Conversions!$AC$2) -> 1049.6176 | E37: =Commodity_prices_MEUR2022!E37*(Conversions!$Z$2/Conversions!$AC$2) -> 1049.6176 | F37: =Commodity_prices_MEUR2022!F37*(Conversions!$Z$2/Conversions!$AC$2) -> 1049.6176 | G37: =Commodity_prices_MEUR2022!G37*(Conversions!$Z$2/Conversions!$AC$2) -> 1049.6176 | H37: =Commodity_prices_MEUR2022!H37*(Conversions!$Z$2/Conversions!$AC$2) -> 1049.6176 | I37: =Commodity_prices_MEUR2022!I37*(Conversions!$Z$2/Conversions!$AC$2) -> 1049.6176 | J37: 45748 | K37: CBS 2025 | L37: invoerwaarde & hoeveelheid, normal portland cement, total of EU & non-EU countries, https://opendata.cbs.nl/#/CBS/nl/dataset/81261ned/table?searchKeywords=cement
A38: Propylene imports - Petrochemical industry | B38: M€2019/Mt | C38: =Commodity_prices_MEUR2022!C38*(Conversions!$Z$2/Conversions!$AC$2) -> 1042.0867 | D38: =Commodity_prices_MEUR2022!D38*(Conversions!$Z$2/Conversions!$AC$2) -> 1042.0867 | E38: =Commodity_prices_MEUR2022!E38*(Conversions!$Z$2/Conversions!$AC$2) -> 1042.0867 | F38: =Commodity_prices_MEUR2022!F38*(Conversions!$Z$2/Conversions!$AC$2) -> 1042.0867 | G38: =Commodity_prices_MEUR2022!G38*(Conversions!$Z$2/Conversions!$AC$2) -> 1042.0867 | H38: =Commodity_prices_MEUR2022!H38*(Conversions!$Z$2/Conversions!$AC$2) -> 1042.0867 | I38: =Commodity_prices_MEUR2022!I38*(Conversions!$Z$2/Conversions!$AC$2) -> 1042.0867 | J38: 45748 | K38: CBS 2025 | L38: invoerwaarde & hoeveelheid, normal portland cement, total of EU & non-EU countries, https://opendata.cbs.nl/#/CBS/nl/dataset/81261ned/table?searchKeywords=cement
A39: Butadiene imports - Petrochemical industry | B39: M€2019/Mt | C39: =Commodity_prices_MEUR2022!C39*(Conversions!$Z$2/Conversions!$AC$2) -> 938.34354 | D39: =Commodity_prices_MEUR2022!D39*(Conversions!$Z$2/Conversions!$AC$2) -> 938.34354 | E39: =Commodity_prices_MEUR2022!E39*(Conversions!$Z$2/Conversions!$AC$2) -> 938.34354 | F39: =Commodity_prices_MEUR2022!F39*(Conversions!$Z$2/Conversions!$AC$2) -> 938.34354 | G39: =Commodity_prices_MEUR2022!G39*(Conversions!$Z$2/Conversions!$AC$2) -> 938.34354 | H39: =Commodity_prices_MEUR2022!H39*(Conversions!$Z$2/Conversions!$AC$2) -> 938.34354 | I39: =Commodity_prices_MEUR2022!I39*(Conversions!$Z$2/Conversions!$AC$2) -> 938.34354 | J39: 45748 | K39: CBS 2025 | L39: invoerwaarde & hoeveelheid, normal portland cement, total of EU & non-EU countries, https://opendata.cbs.nl/#/CBS/nl/dataset/81261ned/table?searchKeywords=cement
A40: Imported aromatics | B40: M€2019/Mt | C40: =Commodity_prices_MEUR2022!C40*(Conversions!$Z$2/Conversions!$AC$2) -> 645.23538 | D40: =Commodity_prices_MEUR2022!D40*(Conversions!$Z$2/Conversions!$AC$2) -> 599.0644 | E40: =Commodity_prices_MEUR2022!E40*(Conversions!$Z$2/Conversions!$AC$2) -> 553.0589 | F40: =Commodity_prices_MEUR2022!F40*(Conversions!$Z$2/Conversions!$AC$2) -> 553.0589 | G40: =Commodity_prices_MEUR2022!G40*(Conversions!$Z$2/Conversions!$AC$2) -> 414.79417 | H40: =Commodity_prices_MEUR2022!H40*(Conversions!$Z$2/Conversions!$AC$2) -> 398.49851 | I40: =Commodity_prices_MEUR2022!I40*(Conversions!$Z$2/Conversions!$AC$2) -> 381.874 | J40: 45582 | L40: Assumed equal to "other oil product imports." Converted to mass terms with NCV 40 MJ/kg.
A41: Imported or purchased iron ore | B41: M€2019/Mt | C41: =Commodity_prices_MEUR2022!C41*(Conversions!$Z$2/Conversions!$AC$2) -> 109.03598 | D41: =Commodity_prices_MEUR2022!D41*(Conversions!$Z$2/Conversions!$AC$2) -> 109.03598 | E41: =Commodity_prices_MEUR2022!E41*(Conversions!$Z$2/Conversions!$AC$2) -> 109.03598 | F41: =Commodity_prices_MEUR2022!F41*(Conversions!$Z$2/Conversions!$AC$2) -> 109.03598 | G41: =Commodity_prices_MEUR2022!G41*(Conversions!$Z$2/Conversions!$AC$2) -> 109.03598 | H41: =Commodity_prices_MEUR2022!H41*(Conversions!$Z$2/Conversions!$AC$2) -> 109.03598 | I41: =Commodity_prices_MEUR2022!I41*(Conversions!$Z$2/Conversions!$AC$2) -> 109.03598 | J41: 45747 | K41: CBS 2025 | L41: Used jan-august 2022 invoerwaarde & hoeveelheid, normal portland cement, total of EU & non-EU countries, https://opendata.cbs.nl/#/CBS/nl/dataset/81261ned/table?searchKeywords=cement
A42: Stock of end-of-life concrete | B42: M€2019/Mt | C42: =Commodity_prices_MEUR2022!C42*(Conversions!$Z$2/Conversions!$AC$2) -> 9.6087767 | D42: =Commodity_prices_MEUR2022!D42*(Conversions!$Z$2/Conversions!$AC$2) -> 9.6087767 | E42: =Commodity_prices_MEUR2022!E42*(Conversions!$Z$2/Conversions!$AC$2) -> 9.6087767 | F42: =Commodity_prices_MEUR2022!F42*(Conversions!$Z$2/Conversions!$AC$2) -> 9.6087767 | G42: =Commodity_prices_MEUR2022!G42*(Conversions!$Z$2/Conversions!$AC$2) -> 9.6087767 | H42: =Commodity_prices_MEUR2022!H42*(Conversions!$Z$2/Conversions!$AC$2) -> 9.6087767 | I42: =Commodity_prices_MEUR2022!I42*(Conversions!$Z$2/Conversions!$AC$2) -> 9.6087767 | J42: 45747 | K42: Zhang et al. 2020 | L42: Table 1, price for secondary material, recycling for concrete industry
A43: Stock of end-of-life ceramic (CTW) | B43: M€2019/Mt | C43: =Commodity_prices_MEUR2022!C43*(Conversions!$Z$2/Conversions!$AC$2) -> 0 | D43: =Commodity_prices_MEUR2022!D43*(Conversions!$Z$2/Conversions!$AC$2) -> 0 | E43: =Commodity_prices_MEUR2022!E43*(Conversions!$Z$2/Conversions!$AC$2) -> 0 | F43: =Commodity_prices_MEUR2022!F43*(Conversions!$Z$2/Conversions!$AC$2) -> 0 | G43: =Commodity_prices_MEUR2022!G43*(Conversions!$Z$2/Conversions!$AC$2) -> 0 | H43: =Commodity_prices_MEUR2022!H43*(Conversions!$Z$2/Conversions!$AC$2) -> 0 | I43: =Commodity_prices_MEUR2022!I43*(Conversions!$Z$2/Conversions!$AC$2) -> 0 | J43: 45747 | K43: Samadi et al 2020 | L43: Assumed to be available at 0 cost because it is a waste material. This should be increased to consider some transport/logistical cost at least - but no source for that yet
A44: Imported/purchased sand | B44: M€2019/Mt | C44: =Commodity_prices_MEUR2022!C44*(Conversions!$Z$2/Conversions!$AC$2) -> 16.297184 | D44: =Commodity_prices_MEUR2022!D44*(Conversions!$Z$2/Conversions!$AC$2) -> 16.297184 | E44: =Commodity_prices_MEUR2022!E44*(Conversions!$Z$2/Conversions!$AC$2) -> 16.297184 | F44: =Commodity_prices_MEUR2022!F44*(Conversions!$Z$2/Conversions!$AC$2) -> 16.297184 | G44: =Commodity_prices_MEUR2022!G44*(Conversions!$Z$2/Conversions!$AC$2) -> 16.297184 | H44: =Commodity_prices_MEUR2022!H44*(Conversions!$Z$2/Conversions!$AC$2) -> 16.297184 | I44: =Commodity_prices_MEUR2022!I44*(Conversions!$Z$2/Conversions!$AC$2) -> 16.297184 | J44: 45747 | K44: CBS 2025 | L44: invoerwaarde & hoeveelheid, normal portland cement, total of EU & non-EU countries, https://opendata.cbs.nl/#/CBS/nl/dataset/81261ned/table?searchKeywords=cement
A45: Imported/purchased gravel/aggregate | B45: M€2019/Mt | C45: =Commodity_prices_MEUR2022!C45*(Conversions!$Z$2/Conversions!$AC$2) -> 9.3342402 | D45: =Commodity_prices_MEUR2022!D45*(Conversions!$Z$2/Conversions!$AC$2) -> 9.3342402 | E45: =Commodity_prices_MEUR2022!E45*(Conversions!$Z$2/Conversions!$AC$2) -> 9.3342402 | F45: =Commodity_prices_MEUR2022!F45*(Conversions!$Z$2/Conversions!$AC$2) -> 9.3342402 | G45: =Commodity_prices_MEUR2022!G45*(Conversions!$Z$2/Conversions!$AC$2) -> 9.3342402 | H45: =Commodity_prices_MEUR2022!H45*(Conversions!$Z$2/Conversions!$AC$2) -> 9.3342402 | I45: =Commodity_prices_MEUR2022!I45*(Conversions!$Z$2/Conversions!$AC$2) -> 9.3342402 | J45: 45747 | K45: Zhang et al. 2019 | L45: Table 4 cost data (virgin material cost)
A46: Imported/purchased cement | B46: M€2019/Mt | C46: =Commodity_prices_MEUR2022!C46*(Conversions!$Z$2/Conversions!$AC$2) -> 77.053238 | D46: =Commodity_prices_MEUR2022!D46*(Conversions!$Z$2/Conversions!$AC$2) -> 77.053238 | E46: =Commodity_prices_MEUR2022!E46*(Conversions!$Z$2/Conversions!$AC$2) -> 77.053238 | F46: =Commodity_prices_MEUR2022!F46*(Conversions!$Z$2/Conversions!$AC$2) -> 77.053238 | G46: =Commodity_prices_MEUR2022!G46*(Conversions!$Z$2/Conversions!$AC$2) -> 77.053238 | H46: =Commodity_prices_MEUR2022!H46*(Conversions!$Z$2/Conversions!$AC$2) -> 77.053238 | I46: =Commodity_prices_MEUR2022!I46*(Conversions!$Z$2/Conversions!$AC$2) -> 77.053238 | J46: 45747 | K46: CBS 2025 | L46: invoerwaarde & hoeveelheid, normal portland cement, total of EU & non-EU countries, https://opendata.cbs.nl/#/CBS/nl/dataset/81261ned/table?searchKeywords=cement
A47: Stock of recovered cement | B47: M€2019/Mt | C47: =Commodity_prices_MEUR2022!C47*(Conversions!$Z$2/Conversions!$AC$2) -> 183.02432 | D47: =Commodity_prices_MEUR2022!D47*(Conversions!$Z$2/Conversions!$AC$2) -> 183.02432 | E47: =Commodity_prices_MEUR2022!E47*(Conversions!$Z$2/Conversions!$AC$2) -> 183.02432 | F47: =Commodity_prices_MEUR2022!F47*(Conversions!$Z$2/Conversions!$AC$2) -> 183.02432 | G47: =Commodity_prices_MEUR2022!G47*(Conversions!$Z$2/Conversions!$AC$2) -> 183.02432 | H47: =Commodity_prices_MEUR2022!H47*(Conversions!$Z$2/Conversions!$AC$2) -> 183.02432 | I47: =Commodity_prices_MEUR2022!I47*(Conversions!$Z$2/Conversions!$AC$2) -> 183.02432 | J47: 45747
A48: Limestone | B48: M€2019/Mt | C48: =Commodity_prices_MEUR2022!C48*(Conversions!$Z$2/Conversions!$AC$2) -> 25.897931 | D48: =Commodity_prices_MEUR2022!D48*(Conversions!$Z$2/Conversions!$AC$2) -> 25.897931 | E48: =Commodity_prices_MEUR2022!E48*(Conversions!$Z$2/Conversions!$AC$2) -> 25.897931 | F48: =Commodity_prices_MEUR2022!F48*(Conversions!$Z$2/Conversions!$AC$2) -> 25.897931 | G48: =Commodity_prices_MEUR2022!G48*(Conversions!$Z$2/Conversions!$AC$2) -> 25.897931 | H48: =Commodity_prices_MEUR2022!H48*(Conversions!$Z$2/Conversions!$AC$2) -> 25.897931 | I48: =Commodity_prices_MEUR2022!I48*(Conversions!$Z$2/Conversions!$AC$2) -> 25.897931 | J48: 45747 | K48: CBS 2025 | L48: Used jan-august 2022 invoerwaarde & hoeveelheid, normal portland cement, total of EU & non-EU countries, https://opendata.cbs.nl/#/CBS/nl/dataset/81261ned/table?searchKeywords=cement
A49: Imported salt | B49: M€2019/Mt | C49: =Commodity_prices_MEUR2022!C49*(Conversions!$Z$2/Conversions!$AC$2) -> 64.098325 | D49: =Commodity_prices_MEUR2022!D49*(Conversions!$Z$2/Conversions!$AC$2) -> 64.098325 | E49: =Commodity_prices_MEUR2022!E49*(Conversions!$Z$2/Conversions!$AC$2) -> 64.098325 | F49: =Commodity_prices_MEUR2022!F49*(Conversions!$Z$2/Conversions!$AC$2) -> 64.098325 | G49: =Commodity_prices_MEUR2022!G49*(Conversions!$Z$2/Conversions!$AC$2) -> 64.098325 | H49: =Commodity_prices_MEUR2022!H49*(Conversions!$Z$2/Conversions!$AC$2) -> 64.098325 | I49: =Commodity_prices_MEUR2022!I49*(Conversions!$Z$2/Conversions!$AC$2) -> 64.098325 | J49: 45749 | K49: Scherpbier & Eerens 2021 | L49: PBL MIDDEN report Table 4, in range for two main salt types. Converted from 2014 EUR to 2022. https://www.pbl.nl/uploads/default/downloads/pbl-2021-decarbonisation-options-for-the-dutch-salt-industry-3477.pdf
A50: Recycled glass | B50: M€2019/Mt | C50: =Commodity_prices_MEUR2022!C50*(Conversions!$Z$2/Conversions!$AC$2) -> 62.502804 | D50: =Commodity_prices_MEUR2022!D50*(Conversions!$Z$2/Conversions!$AC$2) -> 62.502804 | E50: =Commodity_prices_MEUR2022!E50*(Conversions!$Z$2/Conversions!$AC$2) -> 62.502804 | F50: =Commodity_prices_MEUR2022!F50*(Conversions!$Z$2/Conversions!$AC$2) -> 62.502804 | G50: =Commodity_prices_MEUR2022!G50*(Conversions!$Z$2/Conversions!$AC$2) -> 62.502804 | H50: =Commodity_prices_MEUR2022!H50*(Conversions!$Z$2/Conversions!$AC$2) -> 62.502804 | I50: =Commodity_prices_MEUR2022!I50*(Conversions!$Z$2/Conversions!$AC$2) -> 62.502804 | J50: 45869 | K50: Eurostat 2025 | L50: https://ec.europa.eu/eurostat/statistics-explained/index.php?title=Recycling_%E2%80%93_secondary_material_price_indicator
A51: Imported biomethane | B51: M€2019/PJ | C51: =22*(Conversions!$Z$2/Conversions!$AA$2) -> 21.6084 | D51: =22*(Conversions!$Z$2/Conversions!$AA$2) -> 21.6084 | E51: =22*(Conversions!$Z$2/Conversions!$AA$2) -> 21.6084 | F51: =22*(Conversions!$Z$2/Conversions!$AA$2) -> 21.6084 | G51: =22*(Conversions!$Z$2/Conversions!$AA$2) -> 21.6084 | H51: =22*(Conversions!$Z$2/Conversions!$AA$2) -> 21.6084 | I51: =22*(Conversions!$Z$2/Conversions!$AA$2) -> 21.6084 | J51: 45959 | K51: Cluster model | L51: See email from Julia (1 september)

Sheet Commodity_prices_index
A1: Name | B1: 2022 | C1: 2025 | D1: 2030 | E1: 2035 | F1: 2040 | G1: 2045 | H1: 2050 | I1: Updated | J1: Source | K1: Notes
A2: Imported LPG - Refineries | B2: 100 | C2: =B2*Commodity_prices_MEUR2022!D2/Commodity_prices_MEUR2022!C2 -> 92.844319 | D2: =C2*Commodity_prices_MEUR2022!E2/Commodity_prices_MEUR2022!D2 -> 85.714286 | E2: =D2*Commodity_prices_MEUR2022!F2/Commodity_prices_MEUR2022!E2 -> 85.714286 | F2: =E2*Commodity_prices_MEUR2022!G2/Commodity_prices_MEUR2022!F2 -> 64.285714 | G2: =F2*Commodity_prices_MEUR2022!H2/Commodity_prices_MEUR2022!G2 -> 61.760177 | H2: =G2*Commodity_prices_MEUR2022!I2/Commodity_prices_MEUR2022!H2 -> 59.183673 | I2: 45582 | J2: EC Weekly Oil Bulletin | K2: Average of weekly 2022 fuel oil prices for NL reported in oil bulletin. Assumed 45.2 MJ/kg per RVO NCV for LPG, and 1915 l/t as per IEA statistics manual. Future years assume constant ratio for refined products to crude oil.
A3: Imported Naphtha - Refineries | B3: 100 | C3: =B3*Commodity_prices_MEUR2022!D3/Commodity_prices_MEUR2022!C3 -> 92.844319 | D3: =C3*Commodity_prices_MEUR2022!E3/Commodity_prices_MEUR2022!D3 -> 85.714286 | E3: =D3*Commodity_prices_MEUR2022!F3/Commodity_prices_MEUR2022!E3 -> 85.714286 | F3: =E3*Commodity_prices_MEUR2022!G3/Commodity_prices_MEUR2022!F3 -> 64.285714 | G3: =F3*Commodity_prices_MEUR2022!H3/Commodity_prices_MEUR2022!G3 -> 61.760177 | H3: =G3*Commodity_prices_MEUR2022!I3/Commodity_prices_MEUR2022!H3 -> 59.183673 | I3: 45582 | J3: BASF key prices | K3: Base year prices reported by BASF (annual average price for 2022). Projections are based on ratio of naphtha to crude oil price.
A4: Imported Road Fuel - Refineries | B4: 100 | C4: =B4*Commodity_prices_MEUR2022!D4/Commodity_prices_MEUR2022!C4 -> 92.844319 | D4: =C4*Commodity_prices_MEUR2022!E4/Commodity_prices_MEUR2022!D4 -> 85.714286 | E4: =D4*Commodity_prices_MEUR2022!F4/Commodity_prices_MEUR2022!E4 -> 85.714286 | F4: =E4*Commodity_prices_MEUR2022!G4/Commodity_prices_MEUR2022!F4 -> 64.285714 | G4: =F4*Commodity_prices_MEUR2022!H4/Commodity_prices_MEUR2022!G4 -> 61.760177 | H4: =G4*Commodity_prices_MEUR2022!I4/Commodity_prices_MEUR2022!H4 -> 59.183673 | I4: 45582 | J4: EC Weekly Oil Bulletin | K4: Average of weekly 2022 fuel oil prices for NL reported in oil bulletin. Assumed 43.3 MJ/kg per RVO NCV for gasoline, and 1350 l/t as per IEA statistics manual. Future years assume constant ratio for refined products to crude oil.
A5: Imported Kerosene - Refineries | B5: 100 | C5: =B5*Commodity_prices_MEUR2022!D5/Commodity_prices_MEUR2022!C5 -> 92.844319 | D5: =C5*Commodity_prices_MEUR2022!E5/Commodity_prices_MEUR2022!D5 -> 85.714286 | E5: =D5*Commodity_prices_MEUR2022!F5/Commodity_prices_MEUR2022!E5 -> 85.714286 | F5: =E5*Commodity_prices_MEUR2022!G5/Commodity_prices_MEUR2022!F5 -> 64.285714 | G5: =F5*Commodity_prices_MEUR2022!H5/Commodity_prices_MEUR2022!G5 -> 61.760177 | H5: =G5*Commodity_prices_MEUR2022!I5/Commodity_prices_MEUR2022!H5 -> 59.183673 | I5: 45582 | J5: EC Weekly Oil Bulletin; IEA 2024 | K5: Used gas/diesel oil as a proxy. Average of weekly 2022 fuel oil prices for NL reported in oil bulletin. Assumed 43.2 MJ/kg per RVO NCV for gasoline, and 1185 l/t as per IEA statistics manual. Future years assume constant ratio for refined products to crude oil. Well aligned with prices for BE in IEA 2024 (End Use price explorer) - there NL data is only available for 2010.
A6: Imported Fuel Oil - Refineries | B6: 100 | C6: =B6*Commodity_prices_MEUR2022!D6/Commodity_prices_MEUR2022!C6 -> 92.844319 | D6: =C6*Commodity_prices_MEUR2022!E6/Commodity_prices_MEUR2022!D6 -> 85.714286 | E6: =D6*Commodity_prices_MEUR2022!F6/Commodity_prices_MEUR2022!E6 -> 85.714286 | F6: =E6*Commodity_prices_MEUR2022!G6/Commodity_prices_MEUR2022!F6 -> 64.285714 | G6: =F6*Commodity_prices_MEUR2022!H6/Commodity_prices_MEUR2022!G6 -> 61.760177 | H6: =G6*Commodity_prices_MEUR2022!I6/Commodity_prices_MEUR2022!H6 -> 59.183673 | I6: 45582 | J6: EC Weekly Oil Bulletin | K6: Average of weekly 2022 fuel oil prices for NL reported in oil bulletin. Assumed 41 MJ/kg per RVO NCV for residual fuel oil. Future years assume constant ratio for refined products to crude oil.
A7: Imported Other Oil Products - Refineries | B7: 100 | C7: =B7*Commodity_prices_MEUR2022!D7/Commodity_prices_MEUR2022!C7 -> 92.844319 | D7: =C7*Commodity_prices_MEUR2022!E7/Commodity_prices_MEUR2022!D7 -> 85.714286 | E7: =D7*Commodity_prices_MEUR2022!F7/Commodity_prices_MEUR2022!E7 -> 85.714286 | F7: =E7*Commodity_prices_MEUR2022!G7/Commodity_prices_MEUR2022!F7 -> 64.285714 | G7: =F7*Commodity_prices_MEUR2022!H7/Commodity_prices_MEUR2022!G7 -> 61.760177 | H7: =G7*Commodity_prices_MEUR2022!I7/Commodity_prices_MEUR2022!H7 -> 59.183673 | I7: 45579 | J7: - | K7: Assumed equal to fuel oil.
A8: Imported Bionaphtha - Refineries | B8: 100 | C8: =B8*Commodity_prices_MEUR2022!D8/Commodity_prices_MEUR2022!C8 -> 95.714286 | D8: =C8*Commodity_prices_MEUR2022!E8/Commodity_prices_MEUR2022!D8 -> 88.571429 | E8: =D8*Commodity_prices_MEUR2022!F8/Commodity_prices_MEUR2022!E8 -> 81.428571 | F8: =E8*Commodity_prices_MEUR2022!G8/Commodity_prices_MEUR2022!F8 -> 74.285714 | G8: =F8*Commodity_prices_MEUR2022!H8/Commodity_prices_MEUR2022!G8 -> 67.142857 | H8: =G8*Commodity_prices_MEUR2022!I8/Commodity_prices_MEUR2022!H8 -> 60 | I8: 45629 | J8: TNO 2020; IEA Bioenergy 2020 | K8: Assumed 2x price of fossil equivalent in base year, then 40% decline by 2050.
A9: Imported Bioethanol - Refineries | B9: 100 | C9: =B9*Commodity_prices_MEUR2022!D9/Commodity_prices_MEUR2022!C9 -> 91.052373 | D9: =C9*Commodity_prices_MEUR2022!E9/Commodity_prices_MEUR2022!D9 -> 82.100326 | E9: =D9*Commodity_prices_MEUR2022!F9/Commodity_prices_MEUR2022!E9 -> 82.100326 | F9: =E9*Commodity_prices_MEUR2022!G9/Commodity_prices_MEUR2022!F9 -> 82.100326 | G9: =F9*Commodity_prices_MEUR2022!H9/Commodity_prices_MEUR2022!G9 -> 82.100326 | H9: =G9*Commodity_prices_MEUR2022!I9/Commodity_prices_MEUR2022!H9 -> 82.100326 | I9: 45625 | J9: TNO 2024; IEA 2021 | K9: 2022 price from IEA Renewables Market Report. European ethanol price of $1.3/liter. Ethanol market currently at a high point (see market report) due to supply shocks i.e. high price of key feedstocks like corn. We take TNO 2030 value as the longer term stable value, as price shock effects dissipate. Demand pressures are mixed (US & Europe loosening or keeping stable their blending requirements, while new requirements are implemented elsewhere i.e. India). Assumed equal to 2030/2050 price for bioethanol. Note TNO assumes significant price increase to 2050 (~4x).
A10: Imported Biodiesel - Refineries | B10: 100 | C10: =B10*Commodity_prices_MEUR2022!D10/Commodity_prices_MEUR2022!C10 -> 95.714286 | D10: =C10*Commodity_prices_MEUR2022!E10/Commodity_prices_MEUR2022!D10 -> 88.571429 | E10: =D10*Commodity_prices_MEUR2022!F10/Commodity_prices_MEUR2022!E10 -> 81.428571 | F10: =E10*Commodity_prices_MEUR2022!G10/Commodity_prices_MEUR2022!F10 -> 74.285714 | G10: =F10*Commodity_prices_MEUR2022!H10/Commodity_prices_MEUR2022!G10 -> 67.142857 | H10: =G10*Commodity_prices_MEUR2022!I10/Commodity_prices_MEUR2022!H10 -> 60 | I10: 45629 | J10: TNO 2020; IEA Bioenergy 2020 | K10: Assumed 2x price of fossil equivalent in base year, then following trend for biomass import prices.
A11: Imported Biokerosene - Refineries | B11: 100 | C11: =B11*Commodity_prices_MEUR2022!D11/Commodity_prices_MEUR2022!C11 -> 95.714286 | D11: =C11*Commodity_prices_MEUR2022!E11/Commodity_prices_MEUR2022!D11 -> 88.571429 | E11: =D11*Commodity_prices_MEUR2022!F11/Commodity_prices_MEUR2022!E11 -> 81.428571 | F11: =E11*Commodity_prices_MEUR2022!G11/Commodity_prices_MEUR2022!F11 -> 74.285714 | G11: =F11*Commodity_prices_MEUR2022!H11/Commodity_prices_MEUR2022!G11 -> 67.142857 | H11: =G11*Commodity_prices_MEUR2022!I11/Commodity_prices_MEUR2022!H11 -> 60 | I11: 45629 | J11: TNO 2020; IEA Bioenergy 2020 | K11: Assumed 2x price of fossil kerosene in base year, then following trend for biomass import prices
A12: Imported Natural Gas - Final Gas | B12: 100 | C12: =B12*Commodity_prices_MEUR2022!D13/Commodity_prices_MEUR2022!C13 -> 57.777778 | D12: =C12*Commodity_prices_MEUR2022!E13/Commodity_prices_MEUR2022!D13 -> 25.555556 | E12: =D12*Commodity_prices_MEUR2022!F13/Commodity_prices_MEUR2022!E13 -> 22.136766 | F12: =E12*Commodity_prices_MEUR2022!G13/Commodity_prices_MEUR2022!F13 -> 18.709913 | G12: =F12*Commodity_prices_MEUR2022!H13/Commodity_prices_MEUR2022!G13 -> 18.713939 | H12: =G12*Commodity_prices_MEUR2022!I13/Commodity_prices_MEUR2022!H13 -> 18.709913 | I12: 45625 | J12: TNO 2024; IEA 2021 | K12: KEV2024 prices used for 2022, 2025, 2030. Note that 2023 prices are used for 2025. IEA NZE prices used for 2035-2050. No differentiation of prices for national & imported natural gas. Note that IEA's NZE includes declining global gas prices.
A13: Imported LNG - Final Gas | B13: 100 | C13: =B13*Commodity_prices_MEUR2022!D14/Commodity_prices_MEUR2022!C14 -> 57.777778 | D13: =C13*Commodity_prices_MEUR2022!E14/Commodity_prices_MEUR2022!D14 -> 25.555556 | E13: =D13*Commodity_prices_MEUR2022!F14/Commodity_prices_MEUR2022!E14 -> 22.136766 | F13: =E13*Commodity_prices_MEUR2022!G14/Commodity_prices_MEUR2022!F14 -> 18.709913 | G13: =F13*Commodity_prices_MEUR2022!H14/Commodity_prices_MEUR2022!G14 -> 18.713939 | H13: =G13*Commodity_prices_MEUR2022!I14/Commodity_prices_MEUR2022!H14 -> 18.709913 | I13: 45625 | J13: - | K13: Assumed equal to natural gas prices (import & domestic). Highly correlated and close together. (https://globallnghub.com/report-presentation/lng-markets-understanding-the-jkm-ttf-relationship) Average LNG NW Europe price reported by ACER from 1 January 2023-16 October 2024, not used because of volatility of LNG/TTF during the period 2020-2024.
